2018-12-06 11:58:23,305 ERROR: Exception on /index [POST] [in c:\users\rtcjk\appdata\local\programs\python\python36-32\lib\site-packages\flask\app.py:1760]
Traceback (most recent call last):
  File "c:\users\rtcjk\appdata\local\programs\python\python36-32\lib\site-packages\flask\app.py", line 2291, in wsgi_app
    response = self.full_dispatch_request()
  File "c:\users\rtcjk\appdata\local\programs\python\python36-32\lib\site-packages\flask\app.py", line 1814, in full_dispatch_request
    rv = self.handle_user_exception(e)
  File "c:\users\rtcjk\appdata\local\programs\python\python36-32\lib\site-packages\flask\app.py", line 1718, in handle_user_exception
    reraise(exc_type, exc_value, tb)
  File "c:\users\rtcjk\appdata\local\programs\python\python36-32\lib\site-packages\flask\_compat.py", line 35, in reraise
    raise value
  File "c:\users\rtcjk\appdata\local\programs\python\python36-32\lib\site-packages\flask\app.py", line 1812, in full_dispatch_request
    rv = self.dispatch_request()
  File "c:\users\rtcjk\appdata\local\programs\python\python36-32\lib\site-packages\flask\app.py", line 1798, in dispatch_request
    return self.view_functions[rule.endpoint](**req.view_args)
  File "c:\users\rtcjk\appdata\local\programs\python\python36-32\lib\site-packages\flask_login\utils.py", line 261, in decorated_view
    return func(*args, **kwargs)
  File "C:\Projects\AppServer\FlaskApp\app\routes.py", line 25, in index
    post = Post(body.form.data, author=current_user)
NameError: name 'body' is not defined
2018-12-06 11:58:26,007 ERROR: Exception on /index [POST] [in c:\users\rtcjk\appdata\local\programs\python\python36-32\lib\site-packages\flask\app.py:1760]
Traceback (most recent call last):
  File "c:\users\rtcjk\appdata\local\programs\python\python36-32\lib\site-packages\flask\app.py", line 2291, in wsgi_app
    response = self.full_dispatch_request()
  File "c:\users\rtcjk\appdata\local\programs\python\python36-32\lib\site-packages\flask\app.py", line 1814, in full_dispatch_request
    rv = self.handle_user_exception(e)
  File "c:\users\rtcjk\appdata\local\programs\python\python36-32\lib\site-packages\flask\app.py", line 1718, in handle_user_exception
    reraise(exc_type, exc_value, tb)
  File "c:\users\rtcjk\appdata\local\programs\python\python36-32\lib\site-packages\flask\_compat.py", line 35, in reraise
    raise value
  File "c:\users\rtcjk\appdata\local\programs\python\python36-32\lib\site-packages\flask\app.py", line 1812, in full_dispatch_request
    rv = self.dispatch_request()
  File "c:\users\rtcjk\appdata\local\programs\python\python36-32\lib\site-packages\flask\app.py", line 1798, in dispatch_request
    return self.view_functions[rule.endpoint](**req.view_args)
  File "c:\users\rtcjk\appdata\local\programs\python\python36-32\lib\site-packages\flask_login\utils.py", line 261, in decorated_view
    return func(*args, **kwargs)
  File "C:\Projects\AppServer\FlaskApp\app\routes.py", line 25, in index
    post = Post(body.form.data, author=current_user)
NameError: name 'body' is not defined
2018-12-06 11:58:50,841 INFO: FlaskApp [in C:\Projects\AppServer\FlaskApp\app\__init__.py:43]
2018-12-06 11:58:54,795 ERROR: Exception on /index [POST] [in c:\users\rtcjk\appdata\local\programs\python\python36-32\lib\site-packages\flask\app.py:1760]
Traceback (most recent call last):
  File "c:\users\rtcjk\appdata\local\programs\python\python36-32\lib\site-packages\sqlalchemy\engine\base.py", line 1193, in _execute_context
    context)
  File "c:\users\rtcjk\appdata\local\programs\python\python36-32\lib\site-packages\sqlalchemy\engine\default.py", line 509, in do_execute
    cursor.execute(statement, parameters)
sqlite3.InterfaceError: Error binding parameter 0 - probably unsupported type.

The above exception was the direct cause of the following exception:

Traceback (most recent call last):
  File "c:\users\rtcjk\appdata\local\programs\python\python36-32\lib\site-packages\flask\app.py", line 2291, in wsgi_app
    response = self.full_dispatch_request()
  File "c:\users\rtcjk\appdata\local\programs\python\python36-32\lib\site-packages\flask\app.py", line 1814, in full_dispatch_request
    rv = self.handle_user_exception(e)
  File "c:\users\rtcjk\appdata\local\programs\python\python36-32\lib\site-packages\flask\app.py", line 1718, in handle_user_exception
    reraise(exc_type, exc_value, tb)
  File "c:\users\rtcjk\appdata\local\programs\python\python36-32\lib\site-packages\flask\_compat.py", line 35, in reraise
    raise value
  File "c:\users\rtcjk\appdata\local\programs\python\python36-32\lib\site-packages\flask\app.py", line 1812, in full_dispatch_request
    rv = self.dispatch_request()
  File "c:\users\rtcjk\appdata\local\programs\python\python36-32\lib\site-packages\flask\app.py", line 1798, in dispatch_request
    return self.view_functions[rule.endpoint](**req.view_args)
  File "c:\users\rtcjk\appdata\local\programs\python\python36-32\lib\site-packages\flask_login\utils.py", line 261, in decorated_view
    return func(*args, **kwargs)
  File "C:\Projects\AppServer\FlaskApp\app\routes.py", line 27, in index
    db.session.commit()
  File "c:\users\rtcjk\appdata\local\programs\python\python36-32\lib\site-packages\sqlalchemy\orm\scoping.py", line 153, in do
    return getattr(self.registry(), name)(*args, **kwargs)
  File "c:\users\rtcjk\appdata\local\programs\python\python36-32\lib\site-packages\sqlalchemy\orm\session.py", line 954, in commit
    self.transaction.commit()
  File "c:\users\rtcjk\appdata\local\programs\python\python36-32\lib\site-packages\sqlalchemy\orm\session.py", line 467, in commit
    self._prepare_impl()
  File "c:\users\rtcjk\appdata\local\programs\python\python36-32\lib\site-packages\sqlalchemy\orm\session.py", line 447, in _prepare_impl
    self.session.flush()
  File "c:\users\rtcjk\appdata\local\programs\python\python36-32\lib\site-packages\sqlalchemy\orm\session.py", line 2313, in flush
    self._flush(objects)
  File "c:\users\rtcjk\appdata\local\programs\python\python36-32\lib\site-packages\sqlalchemy\orm\session.py", line 2440, in _flush
    transaction.rollback(_capture_exception=True)
  File "c:\users\rtcjk\appdata\local\programs\python\python36-32\lib\site-packages\sqlalchemy\util\langhelpers.py", line 66, in __exit__
    compat.reraise(exc_type, exc_value, exc_tb)
  File "c:\users\rtcjk\appdata\local\programs\python\python36-32\lib\site-packages\sqlalchemy\util\compat.py", line 249, in reraise
    raise value
  File "c:\users\rtcjk\appdata\local\programs\python\python36-32\lib\site-packages\sqlalchemy\orm\session.py", line 2404, in _flush
    flush_context.execute()
  File "c:\users\rtcjk\appdata\local\programs\python\python36-32\lib\site-packages\sqlalchemy\orm\unitofwork.py", line 395, in execute
    rec.execute(self)
  File "c:\users\rtcjk\appdata\local\programs\python\python36-32\lib\site-packages\sqlalchemy\orm\unitofwork.py", line 560, in execute
    uow
  File "c:\users\rtcjk\appdata\local\programs\python\python36-32\lib\site-packages\sqlalchemy\orm\persistence.py", line 181, in save_obj
    mapper, table, insert)
  File "c:\users\rtcjk\appdata\local\programs\python\python36-32\lib\site-packages\sqlalchemy\orm\persistence.py", line 872, in _emit_insert_statements
    execute(statement, params)
  File "c:\users\rtcjk\appdata\local\programs\python\python36-32\lib\site-packages\sqlalchemy\engine\base.py", line 948, in execute
    return meth(self, multiparams, params)
  File "c:\users\rtcjk\appdata\local\programs\python\python36-32\lib\site-packages\sqlalchemy\sql\elements.py", line 269, in _execute_on_connection
    return connection._execute_clauseelement(self, multiparams, params)
  File "c:\users\rtcjk\appdata\local\programs\python\python36-32\lib\site-packages\sqlalchemy\engine\base.py", line 1060, in _execute_clauseelement
    compiled_sql, distilled_params
  File "c:\users\rtcjk\appdata\local\programs\python\python36-32\lib\site-packages\sqlalchemy\engine\base.py", line 1200, in _execute_context
    context)
  File "c:\users\rtcjk\appdata\local\programs\python\python36-32\lib\site-packages\sqlalchemy\engine\base.py", line 1413, in _handle_dbapi_exception
    exc_info
  File "c:\users\rtcjk\appdata\local\programs\python\python36-32\lib\site-packages\sqlalchemy\util\compat.py", line 265, in raise_from_cause
    reraise(type(exception), exception, tb=exc_tb, cause=cause)
  File "c:\users\rtcjk\appdata\local\programs\python\python36-32\lib\site-packages\sqlalchemy\util\compat.py", line 248, in reraise
    raise value.with_traceback(tb)
  File "c:\users\rtcjk\appdata\local\programs\python\python36-32\lib\site-packages\sqlalchemy\engine\base.py", line 1193, in _execute_context
    context)
  File "c:\users\rtcjk\appdata\local\programs\python\python36-32\lib\site-packages\sqlalchemy\engine\default.py", line 509, in do_execute
    cursor.execute(statement, parameters)
sqlalchemy.exc.InterfaceError: <unprintable InterfaceError object>
2018-12-06 12:01:32,025 INFO: FlaskApp [in C:\Projects\AppServer\FlaskApp\app\__init__.py:43]
2018-12-06 12:01:51,823 INFO: FlaskApp [in C:\Projects\AppServer\FlaskApp\app\__init__.py:43]
